# 异常

> 程序在运行过程中，由于我们的编码不规范，或者其他原因一些客观原因，导致我们的程序无法继续运行，此时，程序就会出现异常。
>
> 为了保证程序的健壮性，我们在程序设计里提出了异常处理这个概念。

## 捕获异常

```python
try:
    print('-----test--1---')
    open('123.txt','r')
    print('-----test--2---')
except:
    pass
```

总结：

- 把可能出现问题的代码，放在try中
- 把处理异常的代码，放在except中

## 捕获指定异常

```python
try:
    print(num)
except IOError:
    print('产生错误了')
```

except捕获的错误类型是IOError，而此时程序产生的异常为 NameError ，所以except没有生效。

## 捕获多个指定异常

```python
try:
    print('-----test--1---')
    open('123.txt','r') # 如果123.txt文件不存在，那么会产生 IOError 异常
    print('-----test--2---')
    print(num)# 如果num变量没有定义，那么会产生 NameError 异常

except (IOError,NameError): 
    #如果想通过一次except捕获到多个异常可以用一个元组的方式
    pass
```

当捕获多个异常时，可以把要捕获的异常的名字，放到except 后，并使用元组的方式进行存储

## 捕获异常的信息描述

```try :
try:
    a=1
    b=3
    c=a/b
except Exception as e:
    print(e)
```

e:存储异常的基本信息

## else语句

如果没有捕获到异常，那么就执行else中的事情。

```
try:
...
except:
...
else:
...
```

##  try..finally

> 使用场景：在程序当中，如果一段代码需要执行，即无论是否产生异常都要运行，那么此时就需要使用finally。比如文件的关闭，释放锁，把数据库返回给连接池等等

```python
try:
    f = open('test.txt')
    try:
        while True:
            content = f.readline()
            if len(content) == 0:
                break
            print(content)
    except:
        #如果在读取文件的过程中，产生了异常，那么就会捕获到
        #比如 按下了 ctrl+c
        pass
    finally:
        f.close()
        print('关闭文件')
except:
    print("没有这个文件")
```



# with关键字的使用

对于系统资源如文件、数据库连接、socket 而言，应用程序打开这些资源并执行完业务逻辑之后，必须做的一件事就是要关闭（断开）该资源。

一直创建文件进行 操作却不关闭文件极端情况下会出现 "Too many open files" 的错误，因为系统允许你打开的最大文件数量是有限的。

同样，对于数据库，如果连接数过多而没有及时关闭的话，就可能会出现 "Can not connect to MySQL server Too many connections"，因为数据库连接是一种非常昂贵的资源，不可能无限制的被创建。

来看看如何正确关闭一个文件。

## 普通版：

```python
def m1():
    f = open("output.txt", "w")
    f.write("python之禅")
    f.close()

```

这样写有一个潜在的问题，如果在调用 write 的过程中，出现了异常进而导致后续代码无法继续执行，close 方法无法被正常调用，因此资源就会一直被该程序占用者释放。

## 进阶版：

```python
def m2():
    f = open("output.txt", "w")
    try:
        f.write("python之禅")
    except IOError:
        print("oops error")
    finally:
        f.close()

```

改良版本的程序是对可能发生异常的代码处进行 try 捕获，使用 try/finally 语句，该语句表示如果在 try 代码块中程序出现了异常，后续代码就不再执行，而直接跳转到 except 代码块。而无论如何，finally 块的代码最终都会被执行。因此，只要把 close 放在 finally 代码中，文件就一定会关闭。

## 高级版：

```python
def m3():
    with open("output.txt", "r") as f:
        f.write("Python之禅")

```

一种更加简洁、优雅的方式就是用 with 关键字。open 方法的返回值赋值给变量 f，当离开 with 代码块的时候，系统会自动调用 f.close() 方法， with 的作用和使用 try/finally 语句是一样的。



# 异常的传递

## 1. try嵌套中

```python
try:
    f = open('test.txt')
    try:
        while True:
            content = f.readline()
            if len(content) == 0:
                break
            print(content)
    finally:
        f.close()
        print('关闭文件')
except:
    print("文件读取出错")

```

运行结果:

```python
xxxxxxx--->这是test.txt文件中读取到信息
^C关闭文件
文件读取出错

```

## 2. 函数嵌套调用中

```python
def test1():
    print("----test1-1----")
    print(num)
    print("----test1-2----")


def test2():
    print("----test2-1----")
    test1()
    print("----test2-2----")


def test3():
    try:
        print("----test3-1----")
        test1()
        print("----test3-2----")
    except Exception as result:
        print("捕获到了异常，信息是:%s"%result)

    print("----test3-2----")



test3()
print("------华丽的分割线-----")
test2()

```

运行结果:

```
Traceback (most recent call last):
----test3-1----
----test1-1----
捕获到了异常，信息是:name 'num' is not defined
----test3-2----
  File "E:/培训/code/异常/01.py", line 27, in <module>
------华丽的分割线-----
----test2-1----
----test1-1----
    test2()
  File "E:/培训/code/异常/01.py", line 9, in test2
    test1()
  File "E:/培训/code/异常/01.py", line 3, in test1
    print(num)
NameError: name 'num' is not defined
```



总结：

- 如果try嵌套，那么如果里面的try没有捕获到这个异常，那么外面的try会接收到这个异常，然后进行处理，如果外边的try依然没有捕获到，那么再进行传递。。。
- 如果一个异常是在一个函数中产生的，例如函数A---->函数B---->函数C,而异常是在函数C中产生的，那么如果函数C中没有对这个异常进行处理，那么这个异常会传递到函数B中，如果函数B有异常处理那么就会按照函数B的处理方式进行执行；如果函数B也没有异常处理，那么这个异常会继续传递，以此类推。。。如果所有的函数都没有处理，那么此时就会进行异常的默认处理，即通常见到的那样
- 注意观察上图中，当调用test3函数时，在test1函数内部产生了异常，此异常被传递到test3函数中完成了异常处理，而当异常处理完后，并没有返回到函数test1中进行执行，而是在函数test3中继续执行

# 自定义异常

你可以用raise语句来引发一个异常。异常/错误对象必须有一个名字，且它们应是Error或Exception类的子类

下面是一个引发异常的例子:

```

# 让用户输入内容，如果是长度不在 6~12位，直接报错
class LengthError(Exception):
    def __init__(self, min, max):
      #super().__init__()
        self.min = min
        self.max = max

    def __str__(self):
        return '密码的长度必须是在{}到{}位'.format(self.min, self.max)


def check_password():
    pwd = input('请输入密码')
    if not (12 >= len(pwd) >= 6):
        raise LengthError(6, 12)
    else:
        print('您输入的密码合法,密码是{}'.format(pwd))


try:
    check_password()
except LengthError as e:
    print(e)

else:
    print('欢迎登录我的网站')

```



### 注意

- 以上程序中，关于代码

  ```
  super().__init__()
  
  ```

  的说明

  > 这一行代码，可以调用也可以不调用，建议调用，因为`__init__`方法往往是用来对创建完的对象进行初始化工作，如果在子类中重写了父类的`__init__`方法，即意味着父类中的很多初始化工作没有做，这样就不保证程序的稳定了，所以在以后的开发中，如果重写了父类的`__init__`方法，最好是先调用父类的这个方法，然后再添加自己的功能